Workbook

Sheet Nassau Candy Distributor
A1: Row ID | B1: Order ID | C1: Order Date | D1: Ship Date | E1: Ship Mode | F1: Customer ID | G1: Country/Region | H1: City | I1: State/Province | J1: Postal Code | K1: Division | L1: Region | M1: Product ID | N1: Product Name | O1: Sales | P1: Units | Q1: Gross Profit | R1: Cost
A2: 1 | B2: US-2021-103800-CHO-MIL-31000 | C2: 45294 | D2: 46203 | E2: Standard Class | F2: 103800 | G2: United States | H2: Houston | I2: Texas | J2: 77095 | K2: Chocolate | L2: Interior | M2: CHO-MIL-31000 | N2: Wonka Bar - Milk Chocolate | O2: 6.5 | P2: 2 | Q2: 4.22 | R2: 2.28
A3: 2 | B3: US-2021-112326-CHO-TRI-54000 | C3: 45295 | D3: 46204 | E3: Standard Class | F3: 112326 | G3: United States | H3: Naperville | I3: Illinois | J3: 60540 | K3: Chocolate | L3: Interior | M3: CHO-TRI-54000 | N3: Wonka Bar - Triple Dazzle Caramel | O3: 7.5 | P3: 2 | Q3: 4.9 | R3: 2.6
A4: 3 | B4: US-2021-112326-CHO-NUT-13000 | C4: 45295 | D4: 46204 | E4: Standard Class | F4: 112326 | G4: United States | H4: Naperville | I4: Illinois | J4: 60540 | K4: Chocolate | L4: Interior | M4: CHO-NUT-13000 | N4: Wonka Bar - Nutty Crunch Surprise | O4: 10.47 | P4: 3 | Q4: 7.47 | R4: 3
A5: 4 | B5: US-2021-112326-CHO-SCR-58000 | C5: 45295 | D5: 46204 | E5: Standard Class | F5: 112326 | G5: United States | H5: Naperville | I5: Illinois | J5: 60540 | K5: Chocolate | L5: Interior | M5: CHO-SCR-58000 | N5: Wonka Bar -Scrumdiddlyumptious | O5: 10.8 | P5: 3 | Q5: 7.5 | R5: 3.3
A6: 5 | B6: US-2021-141817-CHO-TRI-54000 | C6: 45296 | D6: 46208 | E6: Standard Class | F6: 141817 | G6: United States | H6: Philadelphia | I6: Pennsylvania | J6: 19143 | K6: Chocolate | L6: Atlantic | M6: CHO-TRI-54000 | N6: Wonka Bar - Triple Dazzle Caramel | O6: 11.25 | P6: 3 | Q6: 7.35 | R6: 3.9
A7: 6 | B7: US-2021-167199-CHO-SCR-58000 | C7: 45297 | D7: 46206 | E7: Standard Class | F7: 167199 | G7: United States | H7: Henderson | I7: Kentucky | J7: 42420 | K7: Chocolate | L7: Gulf | M7: CHO-SCR-58000 | N7: Wonka Bar -Scrumdiddlyumptious | O7: 32.4 | P7: 9 | Q7: 22.5 | R7: 9.9
A8: 7 | B8: US-2021-167199-CHO-TRI-54000 | C8: 45297 | D8: 46206 | E8: Standard Class | F8: 167199 | G8: United States | H8: Henderson | I8: Kentucky | J8: 42420 | K8: Chocolate | L8: Gulf | M8: CHO-TRI-54000 | N8: Wonka Bar - Triple Dazzle Caramel | O8: 7.5 | P8: 2 | Q8: 4.9 | R8: 2.6
A9: 8 | B9: US-2021-106054-CHO-MIL-31000 | C9: 45297 | D9: 46203 | E9: First Class | F9: 106054 | G9: United States | H9: Athens | I9: Georgia | J9: 30605 | K9: Chocolate | L9: Gulf | M9: CHO-MIL-31000 | N9: Wonka Bar - Milk Chocolate | O9: 9.75 | P9: 3 | Q9: 6.33 | R9: 3.42
A10: 9 | B10: US-2021-167199-CHO-NUT-13000 | C10: 45297 | D10: 46206 | E10: Standard Class | F10: 167199 | G10: United States | H10: Henderson | I10: Kentucky | J10: 42420 | K10: Chocolate | L10: Gulf | M10: CHO-NUT-13000 | N10: Wonka Bar - Nutty Crunch Surprise | O10: 6.98 | P10: 2 | Q10: 4.98 | R10: 2
A11: 10 | B11: US-2021-167199-CHO-MIL-31000 | C11: 45297 | D11: 46206 | E11: Standard Class | F11: 167199 | G11: United States | H11: Henderson | I11: Kentucky | J11: 42420 | K11: Chocolate | L11: Gulf | M11: CHO-MIL-31000 | N11: Wonka Bar - Milk Chocolate | O11: 13 | P11: 4 | Q11: 8.44 | R11: 4.56
A12: 11 | B12: US-2021-167199-CHO-MIL-31000 | C12: 45297 | D12: 46206 | E12: Standard Class | F12: 167199 | G12: United States | H12: Henderson | I12: Kentucky | J12: 42420 | K12: Chocolate | L12: Gulf | M12: CHO-MIL-31000 | N12: Wonka Bar - Milk Chocolate | O12: 3.25 | P12: 1 | Q12: 2.11 | R12: 1.14
A13: 12 | B13: US-2021-130813-CHO-MIL-31000 | C13: 45297 | D13: 46204 | E13: Second Class | F13: 130813 | G13: United States | H13: Los Angeles | I13: California | J13: 90049 | K13: Chocolate | L13: Pacific | M13: CHO-MIL-31000 | N13: Wonka Bar - Milk Chocolate | O13: 9.75 | P13: 3 | Q13: 6.33 | R13: 3.42
... A62: 61 | B62: US-2021-110422-CHO-TRI-54000 | C62: 45312 | D62: 46219 | E62: Second Class | F62: 110422 | G62: United States | H62: Miami | I62: Florida | J62: 33180 | K62: Chocolate | L62: Gulf | M62: CHO-TRI-54000 | N62: Wonka Bar - Triple Dazzle Caramel | O62: 11.25 | P62: 3 | Q62: 7.35 | R62: 3.9
A63: 62 | B63: CA-2021-115238-CHO-FUD-51000 | C63: 45312 | D63: 46220 | E63: Standard Class | F63: 115238 | G63: Canada | H63: Toronto | I63: Ontario | J63: M7A | K63: Chocolate | L63: Atlantic | M63: CHO-FUD-51000 | N63: Wonka Bar - Fudge Mallows | O63: 18 | P63: 5 | Q63: 12 | R63: 6
A64: 63 | B64: CA-2021-115238-CHO-MIL-31000 | C64: 45312 | D64: 46220 | E64: Standard Class | F64: 115238 | G64: Canada | H64: Toronto | I64: Ontario | J64: M7A | K64: Chocolate | L64: Atlantic | M64: CHO-MIL-31000 | N64: Wonka Bar - Milk Chocolate | O64: 3.25 | P64: 1 | Q64: 2.11 | R64: 1.14
A65: 64 | B65: CA-2021-115238-CHO-TRI-54000 | C65: 45312 | D65: 46220 | E65: Standard Class | F65: 115238 | G65: Canada | H65: Toronto | I65: Ontario | J65: M7A | K65: Chocolate | L65: Atlantic | M65: CHO-TRI-54000 | N65: Wonka Bar - Triple Dazzle Caramel | O65: 18.75 | P65: 5 | Q65: 12.25 | R65: 6.5
A66: 65 | B66: CA-2021-115238-CHO-FUD-51000 | C66: 45312 | D66: 46220 | E66: Standard Class | F66: 115238 | G66: Canada | H66: Toronto | I66: Ontario | J66: M7A | K66: Chocolate | L66: Atlantic | M66: CHO-FUD-51000 | N66: Wonka Bar - Fudge Mallows | O66: 3.6 | P66: 1 | Q66: 2.4 | R66: 1.2
A67: 66 | B67: CA-2021-115238-CHO-MIL-31000 | C67: 45312 | D67: 46220 | E67: Standard Class | F67: 115238 | G67: Canada | H67: Toronto | I67: Ontario | J67: M7A | K67: Chocolate | L67: Atlantic | M67: CHO-MIL-31000 | N67: Wonka Bar - Milk Chocolate | O67: 32.5 | P67: 10 | Q67: 21.1 | R67: 11.4
A68: 67 | B68: US-2021-146997-CHO-TRI-54000 | C68: 45314 | D68: 46223 | E68: Standard Class | F68: 146997 | G68: United States | H68: Lafayette | I68: Indiana | J68: 47905 | K68: Chocolate | L68: Interior | M68: CHO-TRI-54000 | N68: Wonka Bar - Triple Dazzle Caramel | O68: 11.25 | P68: 3 | Q68: 7.35 | R68: 3.9
A69: 68 | B69: US-2021-102645-CHO-FUD-51000 | C69: 45314 | D69: 46224 | E69: Standard Class | F69: 102645 | G69: United States | H69: Las Vegas | I69: Nevada | J69: 89115 | K69: Chocolate | L69: Pacific | M69: CHO-FUD-51000 | N69: Wonka Bar - Fudge Mallows | O69: 21.6 | P69: 6 | Q69: 14.4 | R69: 7.2
A70: 69 | B70: US-2021-167997-CHO-TRI-54000 | C70: 45317 | D70: 46225 | E70: First Class | F70: 167997 | G70: United States | H70: Rapid City | I70: South Dakota | J70: 57701 | K70: Chocolate | L70: Interior | M70: CHO-TRI-54000 | N70: Wonka Bar - Triple Dazzle Caramel | O70: 7.5 | P70: 2 | Q70: 4.9 | R70: 2.6
A71: 70 | B71: US-2021-155502-CHO-MIL-31000 | C71: 45317 | D71: 46227 | E71: Standard Class | F71: 155502 | G71: United States | H71: Alexandria | I71: Virginia | J71: 22304 | K71: Chocolate | L71: Gulf | M71: CHO-MIL-31000 | N71: Wonka Bar - Milk Chocolate | O71: 9.75 | P71: 3 | Q71: 6.33 | R71: 3.42
A72: 71 | B72: US-2021-155502-CHO-MIL-31000 | C72: 45317 | D72: 46227 | E72: Standard Class | F72: 155502 | G72: United States | H72: Alexandria | I72: Virginia | J72: 22304 | K72: Chocolate | L72: Gulf | M72: CHO-MIL-31000 | N72: Wonka Bar - Milk Chocolate | O72: 9.75 | P72: 3 | Q72: 6.33 | R72: 3.42
A73: 72 | B73: US-2021-167997-CHO-TRI-54000 | C73: 45317 | D73: 46225 | E73: First Class | F73: 167997 | G73: United States | H73: Rapid City | I73: South Dakota | J73: 57701 | K73: Chocolate | L73: Interior | M73: CHO-TRI-54000 | N73: Wonka Bar - Triple Dazzle Caramel | O73: 7.5 | P73: 2 | Q73: 4.9 | R73: 2.6
A74: 73 | B74: US-2021-155502-CHO-MIL-31000 | C74: 45317 | D74: 46227 | E74: Standard Class | F74: 155502 | G74: United States | H74: Alexandria | I74: Virginia | J74: 22304 | K74: Chocolate | L74: Gulf | M74: CHO-MIL-31000 | N74: Wonka Bar - Milk Chocolate | O74: 6.5 | P74: 2 | Q74: 4.22 | R74: 2.28
A75: 74 | B75: US-2021-155502-CHO-TRI-54000 | C75: 45317 | D75: 46227 | E75: Standard Class | F75: 155502 | G75: United States | H75: Alexandria | I75: Virginia | J75: 22304 | K75: Chocolate | L75: Gulf | M75: CHO-TRI-54000 | N75: Wonka Bar - Triple Dazzle Caramel | O75: 11.25 | P75: 3 | Q75: 7.35 | R75: 3.9
A76: 75 | B76: US-2021-155502-CHO-MIL-31000 | C76: 45317 | D76: 46227 | E76: Standard Class | F76: 155502 | G76: United States | H76: Alexandria | I76: Virginia | J76: 22304 | K76: Chocolate | L76: Gulf | M76: CHO-MIL-31000 | N76: Wonka Bar - Milk Chocolate | O76: 26 | P76: 8 | Q76: 16.88 | R76: 9.12
A77: 76 | B77: US-2021-155502-CHO-FUD-51000 | C77: 45317 | D77: 46227 | E77: Standard Class | F77: 155502 | G77: United States | H77: Alexandria | I77: Virginia | J77: 22304 | K77: Chocolate | L77: Gulf | M77: CHO-FUD-51000 | N77: Wonka Bar - Fudge Mallows | O77: 7.2 | P77: 2 | Q77: 4.8 | R77: 2.4
A78: 77 | B78: US-2021-155502-CHO-MIL-31000 | C78: 45317 | D78: 46227 | E78: Standard Class | F78: 155502 | G78: United States | H78: Alexandria | I78: Virginia | J78: 22304 | K78: Chocolate | L78: Gulf | M78: CHO-MIL-31000 | N78: Wonka Bar - Milk Chocolate | O78: 42.25 | P78: 13 | Q78: 27.43 | R78: 14.82
A79: 78 | B79: US-2021-117163-CHO-NUT-13000 | C79: 45318 | D79: 46229 | E79: Standard Class | F79: 117163 | G79: United States | H79: San Diego | I79: California | J79: 92037 | K79: Chocolate | L79: Pacific | M79: CHO-NUT-13000 | N79: Wonka Bar - Nutty Crunch Surprise | O79: 10.47 | P79: 3 | Q79: 7.47 | R79: 3
... A180: 179 | B180: US-2021-114790-CHO-NUT-13000 | C180: 45362 | D180: 46268 | E180: Second Class | F180: 114790 | G180: United States | H180: Richmond | I180: Kentucky | J180: 40475 | K180: Chocolate | L180: Gulf | M180: CHO-NUT-13000 | N180: Wonka Bar - Nutty Crunch Surprise | O180: 10.47 | P180: 3 | Q180: 7.47 | R180: 3
A181: 180 | B181: CA-2021-139675-CHO-SCR-58000 | C181: 45364 | D181: 46273 | E181: Second Class | F181: 139675 | G181: Canada | H181: Calgary | I181: Alberta | J181: T2C | K181: Chocolate | L181: Pacific | M181: CHO-SCR-58000 | N181: Wonka Bar -Scrumdiddlyumptious | O181: 14.4 | P181: 4 | Q181: 10 | R181: 4.4
A182: 181 | B182: CA-2021-139675-CHO-MIL-31000 | C182: 45364 | D182: 46273 | E182: Second Class | F182: 139675 | G182: Canada | H182: Calgary | I182: Alberta | J182: T2C | K182: Chocolate | L182: Pacific | M182: CHO-MIL-31000 | N182: Wonka Bar - Milk Chocolate | O182: 26 | P182: 8 | Q182: 16.88 | R182: 9.12
A183: 182 | B183: US-2021-125521-CHO-FUD-51000 | C183: 45365 | D183: 46274 | E183: Standard Class | F183: 125521 | G183: United States | H183: Chesapeake | I183: Virginia | J183: 23320 | K183: Chocolate | L183: Gulf | M183: CHO-FUD-51000 | N183: Wonka Bar - Fudge Mallows | O183: 14.4 | P183: 4 | Q183: 9.6 | R183: 4.8
A184: 183 | B184: US-2021-157623-CHO-FUD-51000 | C184: 45365 | D184: 46273 | E184: Standard Class | F184: 157623 | G184: United States | H184: Huntington Beach | I184: California | J184: 92646 | K184: Chocolate | L184: Pacific | M184: CHO-FUD-51000 | N184: Wonka Bar - Fudge Mallows | O184: 3.6 | P184: 1 | Q184: 2.4 | R184: 1.2
A185: 184 | B185: US-2021-114510-CHO-NUT-13000 | C185: 45365 | D185: 46274 | E185: Standard Class | F185: 114510 | G185: United States | H185: Logan | I185: Utah | J185: 84321 | K185: Chocolate | L185: Pacific | M185: CHO-NUT-13000 | N185: Wonka Bar - Nutty Crunch Surprise | O185: 13.96 | P185: 4 | Q185: 9.96 | R185: 4
A186: 185 | B186: US-2021-114510-CHO-NUT-13000 | C186: 45365 | D186: 46274 | E186: Standard Class | F186: 114510 | G186: United States | H186: Logan | I186: Utah | J186: 84321 | K186: Chocolate | L186: Pacific | M186: CHO-NUT-13000 | N186: Wonka Bar - Nutty Crunch Surprise | O186: 6.98 | P186: 2 | Q186: 4.98 | R186: 2
A187: 186 | B187: US-2021-100293-CHO-NUT-13000 | C187: 45365 | D187: 46273 | E187: Standard Class | F187: 100293 | G187: United States | H187: Jacksonville | I187: Florida | J187: 32216 | K187: Chocolate | L187: Gulf | M187: CHO-NUT-13000 | N187: Wonka Bar - Nutty Crunch Surprise | O187: 20.94 | P187: 6 | Q187: 14.94 | R187: 6
A188: 187 | B188: US-2021-157623-CHO-NUT-13000 | C188: 45365 | D188: 46273 | E188: Standard Class | F188: 157623 | G188: United States | H188: Huntington Beach | I188: California | J188: 92646 | K188: Chocolate | L188: Pacific | M188: CHO-NUT-13000 | N188: Wonka Bar - Nutty Crunch Surprise | O188: 6.98 | P188: 2 | Q188: 4.98 | R188: 2
...

Sheet Data_Profile
A1: Field | B1: Data Type | C1: Missing | D1: Unique
A2: Row ID | B2: Integer | C2: =COUNTIF('Nassau Candy Distributor'!A2:A10195,"") -> 0 | D2: {=COUNTA(_xlfn.UNIQUE(_xlfn._xlws.FILTER('Nassau Candy Distributor'!A2:A10195,'Nassau Candy Distributor'!A2:A10195<>"")))} -> 10194
A3: Order ID | B3: Text | C3: =COUNTIF('Nassau Candy Distributor'!B2:B10195,"") -> 0 | D3: {=COUNTA(_xlfn.UNIQUE(_xlfn._xlws.FILTER('Nassau Candy Distributor'!B2:B10195,'Nassau Candy Distributor'!B2:B10195<>"")))} -> 8549
A4: Order Date | B4: Date | C4: =COUNTIF('Nassau Candy Distributor'!C2:C10195,"") -> 0 | D4: {=COUNTA(_xlfn.UNIQUE(_xlfn._xlws.FILTER('Nassau Candy Distributor'!C2:C10195,'Nassau Candy Distributor'!C2:C10195<>"")))} -> 717
A5: Ship Date | B5: Date | C5: =COUNTIF('Nassau Candy Distributor'!D2:D10195,"") -> 0 | D5: {=COUNTA(_xlfn.UNIQUE(_xlfn._xlws.FILTER('Nassau Candy Distributor'!D2:D10195,'Nassau Candy Distributor'!D2:D10195<>"")))} -> 1338
A6: Ship Mode | B6: Text | C6: =COUNTIF('Nassau Candy Distributor'!E2:E10195,"") -> 0 | D6: {=COUNTA(_xlfn.UNIQUE(_xlfn._xlws.FILTER('Nassau Candy Distributor'!E2:E10195,'Nassau Candy Distributor'!E2:E10195<>"")))} -> 4
A7: Customer | B7: Integer | C7: =COUNTIF('Nassau Candy Distributor'!F2:F10195,"") -> 0 | D7: {=COUNTA(_xlfn.UNIQUE(_xlfn._xlws.FILTER('Nassau Candy Distributor'!F2:F10195,'Nassau Candy Distributor'!F2:F10195<>"")))} -> 5044
A8: Country/Region | B8: Text | C8: =COUNTIF('Nassau Candy Distributor'!G2:G10195,"") -> 0 | D8: {=COUNTA(_xlfn.UNIQUE(_xlfn._xlws.FILTER('Nassau Candy Distributor'!G2:G10195,'Nassau Candy Distributor'!G2:G10195<>"")))} -> 2
A9: City | B9: Text | C9: =COUNTIF('Nassau Candy Distributor'!H2:H10195,"") -> 0 | D9: {=COUNTA(_xlfn.UNIQUE(_xlfn._xlws.FILTER('Nassau Candy Distributor'!H2:H10195,'Nassau Candy Distributor'!H2:H10195<>"")))} -> 542
A10: State/Province | B10: Text | C10: =COUNTIF('Nassau Candy Distributor'!I2:I10195,"") -> 0 | D10: {=COUNTA(_xlfn.UNIQUE(_xlfn._xlws.FILTER('Nassau Candy Distributor'!I2:I10195,'Nassau Candy Distributor'!I2:I10195<>"")))} -> 59
A11: Postal Code | B11: Integer | C11: =COUNTIF('Nassau Candy Distributor'!J2:J10195,"") -> 0 | D11: {=COUNTA(_xlfn.UNIQUE(_xlfn._xlws.FILTER('Nassau Candy Distributor'!J2:J10195,'Nassau Candy Distributor'!J2:J10195<>"")))} -> 654
A12: Division | B12: Text | C12: =COUNTIF('Nassau Candy Distributor'!K2:K10195,"") -> 0 | D12: {=COUNTA(_xlfn.UNIQUE(_xlfn._xlws.FILTER('Nassau Candy Distributor'!K2:K10195,'Nassau Candy Distributor'!K2:K10195<>"")))} -> 3
A13: Region | B13: Text | C13: =COUNTIF('Nassau Candy Distributor'!L2:L10195,"") -> 0 | D13: {=COUNTA(_xlfn.UNIQUE(_xlfn._xlws.FILTER('Nassau Candy Distributor'!L2:L10195,'Nassau Candy Distributor'!L2:L10195<>"")))} -> 4
A14: Product ID | B14: Text | C14: =COUNTIF('Nassau Candy Distributor'!M2:M10195,"") -> 0 | D14: {=COUNTA(_xlfn.UNIQUE(_xlfn._xlws.FILTER('Nassau Candy Distributor'!M2:M10195,'Nassau Candy Distributor'!M2:M10195<>"")))} -> 15
A15: Product Name | B15: Text | C15: =COUNTIF('Nassau Candy Distributor'!N2:N10195,"") -> 0 | D15: {=COUNTA(_xlfn.UNIQUE(_xlfn._xlws.FILTER('Nassau Candy Distributor'!N2:N10195,'Nassau Candy Distributor'!N2:N10195<>"")))} -> 15
A16: Sales | B16: Decimal | C16: =COUNTIF('Nassau Candy Distributor'!O2:O10195,"") -> 0 | D16: {=COUNTA(_xlfn.UNIQUE(_xlfn._xlws.FILTER('Nassau Candy Distributor'!O2:O10195,'Nassau Candy Distributor'!O2:O10195<>"")))} -> 88
A17: Unit | B17: Integer | C17: =COUNTIF('Nassau Candy Distributor'!P2:P10195,"") -> 0 | D17: {=COUNTA(_xlfn.UNIQUE(_xlfn._xlws.FILTER('Nassau Candy Distributor'!P2:P10195,'Nassau Candy Distributor'!P2:P10195<>"")))} -> 14
A18: Gross Profit | B18: Decimal | C18: =COUNTIF('Nassau Candy Distributor'!Q2:Q10195,"") -> 0 | D18: {=COUNTA(_xlfn.UNIQUE(_xlfn._xlws.FILTER('Nassau Candy Distributor'!Q2:Q10195,'Nassau Candy Distributor'!Q2:Q10195<>"")))} -> 121
A19: Cost | B19: Decimal | C19: =COUNTIF('Nassau Candy Distributor'!R2:R10195,"") -> 0 | D19: {=COUNTA(_xlfn.UNIQUE(_xlfn._xlws.FILTER('Nassau Candy Distributor'!R2:R10195,'Nassau Candy Distributor'!R2:R10195<>"")))} -> 95

Sheet Pivot_Analysis
A1: Row Labels | B1: Count of Order ID | C1: Sum of Sales | D1: Sum of Units | E1: Sum of Gross Profit
A2: First Class | B2: 1548 | C2: 21319.39 | D2: 5724 | E2: 14011.09
A3: Same Day | B3: 547 | C3: 7113.67 | D3: 1975 | E3: 4700.73
A4: Second Class | B4: 1979 | C4: 27860.22 | D4: 7546 | E4: 18306.52
A5: Standard Class | B5: 6120 | C5: 85490.35 | D5: 23409 | E5: 56424.46
A6: Grand Total | B6: 10194 | C6: 141783.63 | D6: 38654 | E6: 93442.8
A8: Row Labels | B8: Count of Order ID | C8: Sum of Sales | D8: Sum of Units | E8: Sum of Gross Profit
A9: Atlantic | B9: 2986 | C9: 41197.24 | D9: 11159 | E9: 26973.7
A10: Gulf | B10: 1620 | C10: 22247.26 | D10: 6209 | E10: 14700.67
A11: Interior | B11: 2335 | C11: 32037.6 | D11: 8820 | E11: 21282.49
A12: Pacific | B12: 3253 | C12: 46301.53 | D12: 12466 | E12: 30485.94
A13: Grand Total | B13: 10194 | C13: 141783.63 | D13: 38654 | E13: 93442.8
A15: Row Labels | B15: Count of Order ID | C15: Sum of Sales | D15: Sum of Gross Profit
A16: Chocolate | B16: 9844 | C16: 131692.9 | D16: 88824.62
A17: Other | B17: 310 | C17: 9663.25 | D17: 4333.45
A18: Sugar | B18: 40 | C18: 427.48 | D18: 284.73
A19: Grand Total | B19: 10194 | C19: 141783.63 | D19: 93442.8
